INFO 2025-08-03 21:38:47,474 django.utils.autoreload - Watching for file changes with StatReloader
INFO 2025-08-03 21:39:42,374 django.server - "POST //api/accounts/register/ HTTP/1.1" 201 34
INFO 2025-08-03 21:39:58,026 django.server - "POST //api/accounts/login/ HTTP/1.1" 200 581
INFO 2025-08-03 21:41:34,979 django.utils.autoreload - /app/accounts/serializers.py changed, reloading.
INFO 2025-08-03 21:41:35,944 django.utils.autoreload - Watching for file changes with StatReloader
INFO 2025-08-03 21:42:15,971 django.utils.autoreload - /app/accounts/views.py changed, reloading.
INFO 2025-08-03 21:42:16,867 django.utils.autoreload - Watching for file changes with StatReloader
INFO 2025-08-03 21:43:24,269 django.utils.autoreload - /app/accounts/urls.py changed, reloading.
INFO 2025-08-03 21:43:25,113 django.utils.autoreload - Watching for file changes with StatReloader
ERROR 2025-08-03 21:44:30,493 django.request - Internal Server Error: /api/accounts/me/
Traceback (most recent call last):
  File "/usr/local/lib/python3.11/site-packages/django/core/handlers/exception.py", line 55, in inner
    response = get_response(request)
               ^^^^^^^^^^^^^^^^^^^^^
  File "/usr/local/lib/python3.11/site-packages/django/core/handlers/base.py", line 197, in _get_response
    response = wrapped_callback(request, *callback_args, **callback_kwargs)
               ^^^^^^^^^^^^^^^^^^^^^^^^^^^^^^^^^^^^^^^^^^^^^^^^^^^^^^^^^^^^
  File "/usr/local/lib/python3.11/site-packages/django/views/decorators/csrf.py", line 65, in _view_wrapper
    return view_func(request, *args, **kwargs)
           ^^^^^^^^^^^^^^^^^^^^^^^^^^^^^^^^^^^
  File "/usr/local/lib/python3.11/site-packages/django/views/generic/base.py", line 105, in view
    return self.dispatch(request, *args, **kwargs)
           ^^^^^^^^^^^^^^^^^^^^^^^^^^^^^^^^^^^^^^^
  File "/usr/local/lib/python3.11/site-packages/rest_framework/views.py", line 515, in dispatch
    response = self.handle_exception(exc)
               ^^^^^^^^^^^^^^^^^^^^^^^^^^
  File "/usr/local/lib/python3.11/site-packages/rest_framework/views.py", line 475, in handle_exception
    self.raise_uncaught_exception(exc)
  File "/usr/local/lib/python3.11/site-packages/rest_framework/views.py", line 486, in raise_uncaught_exception
    raise exc
  File "/usr/local/lib/python3.11/site-packages/rest_framework/views.py", line 512, in dispatch
    response = handler(request, *args, **kwargs)
               ^^^^^^^^^^^^^^^^^^^^^^^^^^^^^^^^^
  File "/usr/local/lib/python3.11/site-packages/rest_framework/generics.py", line 212, in get
    return self.retrieve(request, *args, **kwargs)
           ^^^^^^^^^^^^^^^^^^^^^^^^^^^^^^^^^^^^^^^
  File "/usr/local/lib/python3.11/site-packages/rest_framework/mixins.py", line 56, in retrieve
    return Response(serializer.data)
                    ^^^^^^^^^^^^^^^
  File "/usr/local/lib/python3.11/site-packages/rest_framework/serializers.py", line 573, in data
    ret = super().data
          ^^^^^^^^^^^^
  File "/usr/local/lib/python3.11/site-packages/rest_framework/serializers.py", line 251, in data
    self._data = self.to_representation(self.instance)
                 ^^^^^^^^^^^^^^^^^^^^^^^^^^^^^^^^^^^^^
  File "/usr/local/lib/python3.11/site-packages/rest_framework/serializers.py", line 525, in to_representation
    for field in fields:
  File "/usr/local/lib/python3.11/site-packages/rest_framework/serializers.py", line 386, in _readable_fields
    for field in self.fields.values():
                 ^^^^^^^^^^^
  File "/usr/local/lib/python3.11/site-packages/django/utils/functional.py", line 47, in __get__
    res = instance.__dict__[self.name] = self.func(instance)
                                         ^^^^^^^^^^^^^^^^^^^
  File "/usr/local/lib/python3.11/site-packages/rest_framework/serializers.py", line 375, in fields
    fields[key] = value
    ~~~~~~^^^^^
  File "/usr/local/lib/python3.11/site-packages/rest_framework/utils/serializer_helpers.py", line 167, in __setitem__
    field.bind(field_name=key, parent=self.serializer)
  File "/usr/local/lib/python3.11/site-packages/rest_framework/fields.py", line 358, in bind
    assert self.source != field_name, (
           ^^^^^^^^^^^^^^^^^^^^^^^^^
AssertionError: It is redundant to specify `source='profile'` on field 'UserProfileSerializer' in serializer 'UserWithProfileSerializer', because it is the same as the field name. Remove the `source` keyword argument.
ERROR 2025-08-03 21:44:30,501 django.server - "GET //api/accounts/me/ HTTP/1.1" 500 129959
INFO 2025-08-03 21:45:42,003 django.utils.autoreload - /app/accounts/serializers.py changed, reloading.
INFO 2025-08-03 21:45:42,861 django.utils.autoreload - Watching for file changes with StatReloader
INFO 2025-08-03 21:45:53,739 django.server - "GET //api/accounts/me/ HTTP/1.1" 200 255
INFO 2025-08-03 21:54:09,571 django.utils.autoreload - /app/accounts/serializers.py changed, reloading.
INFO 2025-08-03 21:54:11,927 django.utils.autoreload - Watching for file changes with StatReloader
INFO 2025-08-03 21:54:40,157 django.utils.autoreload - /app/accounts/views.py changed, reloading.
INFO 2025-08-03 21:54:41,499 django.utils.autoreload - Watching for file changes with StatReloader
INFO 2025-08-03 21:55:01,456 django.utils.autoreload - /app/accounts/views.py changed, reloading.
INFO 2025-08-03 21:55:02,354 django.utils.autoreload - Watching for file changes with StatReloader
INFO 2025-08-03 21:55:29,144 django.utils.autoreload - /app/accounts/urls.py changed, reloading.
INFO 2025-08-03 21:55:30,794 django.utils.autoreload - Watching for file changes with StatReloader
